<?xml version="1.0" ?>
<robot name="chusa_bot">

  <link name="base_footprint"/>

  <joint name="base_joint" type="fixed">
    <parent link="base_footprint"/>
    <child link="base_link"/>
    <origin xyz="0.0 0.0 0.068"/>
  </joint>

  <link name="base_link">
    <visual>
      <origin xyz="0.0 0.0 0.0" rpy="0 0 0"/>
      <geometry>
        <box size="0.215 0.1 0.049"/>
      </geometry>
      <material name="black">
        <color rgba="1 1 1 1"/>
      </material>
    </visual>
    <collision>
      <origin xyz="0.0 0.0 0.0" rpy="0 0 0"/>
      <geometry>
        <box size="0.215 0.1 0.049"/>
      </geometry>
    </collision>
    <inertial>
      <origin xyz="0.0 0.0 0.0" rpy="0 0 0"/>
      <mass value="0.106"/>
      <inertia ixx="4.079e-004" ixy="-4.004e-007" ixz="0"
               iyy="1.017e-004" iyz="0"
               izz="5.092e-004" />
    </inertial>
  </link>

  <joint name="imu_joint" type="fixed">
    <parent link="base_link"/>
    <child link="imu_mpu9250"/>
    <origin xyz="0 0 -0.0245" rpy="0 0 0"/>
  </joint>

  <link name="imu_mpu9250" type="imu">
    <visual>
      <origin xyz="0.0 0.0 0.0" rpy="0 0 0"/>
      <geometry>
        <box size="0.019 0.029 0.003"/>
      </geometry>
      <material name="blue">
        <color rgba="0 0 1 1"/>
      </material>
    </visual>
    <inertial>
      <origin xyz="0.0 0.0 0.0" rpy="0 0 0"/>
      <mass value="0.002"/>
      <inertia ixx="1.417e-007" ixy="0" ixz="0"
               iyy="6.167e-007" iyz="0"
               izz="2.003e-007" />
    </inertial>
  </link>

  <joint name="base_scan_joint" type="fixed">
    <parent link="base_link"/>
    <child link="base_scan"/>
    <origin xyz="0.05 0 0.0545"/>
  </joint>

  <link name="base_scan">
    <visual>
      <origin xyz="0.0 0.0 0.0" rpy="0 0 0"/>
      <geometry>
        <box size="0.1 0.075 0.06"/>
      </geometry>
      <material name="green">
        <color rgba="0 1 0 1"/>
      </material>
    </visual>
    <collision>
      <origin xyz="0.0 0.0 0.0" rpy="0 0 0"/>
      <geometry>
        <box size="0.1 0.075 0.06"/>
      </geometry>
    </collision>
    <inertial>
      <origin xyz="0.0 0.0 0.0" rpy="0 0 0"/>
      <mass value="0.213"/>
      <inertia ixx="2.412e-04" ixy="0" ixz="0"
               iyy="1.636e-04" iyz="0"
               izz="2.771e-04" />
    </inertial>
  </link>

  <joint name="left_motor1_joint" type="fixed">
    <parent link="base_link"/>
    <child link="left_motor1"/>
    <origin xyz="0.002 0.038 -0.0355"/>
  </joint>

  <link name="left_motor1">
    <visual>
      <origin xyz="0.0 0.0 0.0" rpy="0 0 0"/>
      <geometry>
        <box size="0.065 0.024 0.022"/>
      </geometry>
      <material name="red">
        <color rgba="1 0 0 1"/>
      </material>
    </visual>
    <collision>
      <origin xyz="0.0 0.0 0.0" rpy="0 0 0"/>
      <geometry>
        <box size="0.065 0.024 0.022"/>
      </geometry>
    </collision>
    <inertial>
      <origin xyz="0.0 0.0 0.0" rpy="0 0 0"/>
      <mass value="0.036"/>
      <inertia ixx="3.18e-06" ixy="0" ixz="0"
               iyy="1.413e-05" iyz="0"
               izz="1.44e-05" />
    </inertial>
  </link>

  <joint name="left_wheel1_joint" type="continuous">
    <parent link="left_motor1"/>
    <child link="left_wheel1"/>
    <origin xyz="0.0215 0.0245 0.0"/>
    <axis xyz="0 -1 0"/>
  </joint>

  <link name="left_wheel1">
    <visual>
      <origin xyz="0.0 0.0 0.0" rpy="1.57 0 0"/>
      <geometry>
        <cylinder radius="0.0325" length="0.025"/>
      </geometry>
      <material name="yellow">
        <color rgba="1 1 0 1"/>
      </material>
    </visual>
    <collision>
      <origin xyz="0.0 0.0 0.0" rpy="1.57 0 0"/>
      <geometry>
        <cylinder radius="0.0325" length="0.025"/>
      </geometry>
    </collision>
    <inertial>
      <origin xyz="0.0 0.0 0.0" rpy="1.57 0 0"/>
      <mass value="0.036"/>
      <inertia ixx="1.138e-05" ixy="0" ixz="0"
               iyy="1.138e-05" iyz="0"
               izz="1.901e-05" />
    </inertial>
  </link>

  <joint name="left_motor2_joint" type="fixed">
    <parent link="base_link"/>
    <child link="left_motor2"/>
    <origin xyz="-0.075 0.038 -0.0355"/>
  </joint>

  <link name="left_motor2">
    <visual>
      <origin xyz="0.0 0.0 0.0" rpy="0 0 0"/>
      <geometry>
        <box size="0.065 0.024 0.022"/>
      </geometry>
      <material name="red">
        <color rgba="1 0 0 1"/>
      </material>
    </visual>
    <collision>
      <origin xyz="0.0 0.0 0.0" rpy="0 0 0"/>
      <geometry>
        <box size="0.065 0.024 0.022"/>
      </geometry>
    </collision>
    <inertial>
      <origin xyz="0.0 0.0 0.0" rpy="0 0 0"/>
      <mass value="0.036"/>
      <inertia ixx="3.18e-06" ixy="0" ixz="0"
               iyy="1.413e-05" iyz="0"
               izz="1.44e-05" />
    </inertial>
  </link>

  <joint name="left_wheel2_joint" type="continuous">
    <parent link="left_motor2"/>
    <child link="left_wheel2"/>
    <origin xyz="0.0215 0.0245 0.0"/>
    <axis xyz="0 -1 0"/>
  </joint>

  <link name="left_wheel2">
    <visual>
      <origin xyz="0.0 0.0 0.0" rpy="1.57 0 0"/>
      <geometry>
        <cylinder radius="0.0325" length="0.025"/>
      </geometry>
      <material name="yellow">
        <color rgba="1 1 0 1"/>
      </material>
    </visual>
    <collision>
      <origin xyz="0.0 0.0 0.0" rpy="1.57 0 0"/>
      <geometry>
        <cylinder radius="0.0325" length="0.025"/>
      </geometry>
    </collision>
    <inertial>
      <origin xyz="0.0 0.0 0.0" rpy="1.57 0 0"/>
      <mass value="0.036"/>
      <inertia ixx="1.138e-05" ixy="0" ixz="0"
               iyy="1.138e-05" iyz="0"
               izz="1.901e-05" />
    </inertial>
  </link>

  <joint name="right_motor1_joint" type="fixed">
    <parent link="base_link"/>
    <child link="right_motor1"/>
    <origin xyz="0.002 -0.038 -0.0355"/>
  </joint>

  <link name="right_motor1">
    <visual>
      <origin xyz="0.0 0.0 0.0" rpy="0 0 0"/>
      <geometry>
        <box size="0.065 0.024 0.022"/>
      </geometry>
      <material name="red">
        <color rgba="1 0 0 1"/>
      </material>
    </visual>
    <collision>
      <origin xyz="0.0 0.0 0.0" rpy="0 0 0"/>
      <geometry>
        <box size="0.065 0.024 0.022"/>
      </geometry>
    </collision>
    <inertial>
      <origin xyz="0.0 0.0 0.0" rpy="0 0 0"/>
      <mass value="0.036"/>
      <inertia ixx="3.18e-06" ixy="0" ixz="0"
               iyy="1.413e-05" iyz="0"
               izz="1.44e-05" />
    </inertial>
  </link>

  <joint name="right_wheel1_joint" type="continuous">
    <parent link="right_motor1"/>
    <child link="right_wheel1"/>
    <origin xyz="0.0215 -0.0245 0.0"/>
    <axis xyz="0 -1 0"/>
  </joint>

  <link name="right_wheel1">
    <visual>
      <origin xyz="0.0 0.0 0.0" rpy="1.57 0 0"/>
      <geometry>
        <cylinder radius="0.0325" length="0.025"/>
      </geometry>
      <material name="yellow">
        <color rgba="1 1 0 1"/>
      </material>
    </visual>
    <collision>
      <origin xyz="0.0 0.0 0.0" rpy="1.57 0 0"/>
      <geometry>
        <cylinder radius="0.0325" length="0.025"/>
      </geometry>
    </collision>
    <inertial>
      <origin xyz="0.0 0.0 0.0" rpy="1.57 0 0"/>
      <mass value="0.036"/>
      <inertia ixx="1.138e-05" ixy="0" ixz="0"
               iyy="1.138e-05" iyz="0"
               izz="1.901e-05" />
    </inertial>
  </link>

  <joint name="right_motor2_joint" type="fixed">
    <parent link="base_link"/>
    <child link="right_motor2"/>
    <origin xyz="-0.075 -0.038 -0.0355"/>
  </joint>

  <link name="right_motor2">
    <visual>
      <origin xyz="0.0 0.0 0.0" rpy="0 0 0"/>
      <geometry>
        <box size="0.065 0.024 0.022"/>
      </geometry>
      <material name="red">
        <color rgba="1 0 0 1"/>
      </material>
    </visual>
    <collision>
      <origin xyz="0.0 0.0 0.0" rpy="0 0 0"/>
      <geometry>
        <box size="0.065 0.024 0.022"/>
      </geometry>
    </collision>
    <inertial>
      <origin xyz="0.0 0.0 0.0" rpy="0 0 0"/>
      <mass value="0.036"/>
      <inertia ixx="3.18e-06" ixy="0" ixz="0"
               iyy="1.413e-05" iyz="0"
               izz="1.44e-05" />
    </inertial>
  </link>
  
  <joint name="right_wheel2_joint" type="continuous">
    <parent link="right_motor2"/>
    <child link="right_wheel2"/>
    <origin xyz="0.0215 -0.0245 0.0"/>
    <axis xyz="0 -1 0"/>
  </joint>

  <link name="right_wheel2">
    <visual>
      <origin xyz="0.0 0.0 0.0" rpy="1.57 0 0"/>
      <geometry>
        <cylinder radius="0.0325" length="0.025"/>
      </geometry>
      <material name="yellow">
        <color rgba="1 1 0 1"/>
      </material>
    </visual>
    <collision>
      <origin xyz="0.0 0.0 0.0" rpy="1.57 0 0"/>
      <geometry>
        <cylinder radius="0.0325" length="0.025"/>
      </geometry>
    </collision>
    <inertial>
      <origin xyz="0.0 0.0 0.0" rpy="1.57 0 0"/>
      <mass value="0.036"/>
      <inertia ixx="1.138e-05" ixy="0" ixz="0"
               iyy="1.138e-05" iyz="0"
               izz="1.901e-05" />
    </inertial>
  </link>
  

</robot>
